Workbook

Sheet KPI Summary Report
A1: IFL Delivery Achievement Report - May 2026
A2: Target : | B2: 0.985
D3: BEFORE INVESTIGATION RESULT (IFL) | G3: AFTER INVESTIGATION RESULT (PDC)
A4: CW | B4: Shipment Dates | C4: No. of shipments | D4: Achieved | E4: Not Achieved | F4: % of Achievement | G4: Achieved | H4: Not Achieved | I4: % of Achievement
A5: CZ/KD
A6: CW19 | B6: 04/05/2026 - 08/05/2026 | C6: =CZ!D3 -> 6 | D6: =C6-E6 -> 5 | E6: =CZ!D4 -> 1 | F6: =(C6-E6)/C6*1 -> 0.83333333 | G6: =C6-H6 -> 6 | H6: =CZ!D9 -> 0 | I6: =(C6-H6)/C6 -> 1
A7: CW20 | B7: 11/05/2026 - 15/05/2026 | C7: =CZ!G3 -> 6 | D7: =C7-E7 -> 6 | E7: =CZ!G4 -> 0 | F7: =(C7-E7)/C7*1 -> 1 | G7: =C7-H7 -> 6 | H7: =CZ!G9 -> 0 | I7: =(C7-H7)/C7 -> 1
A8: CW21 | B8: 18/05/2026 - 22/05/2026 | C8: =CZ!J3 -> 6 | D8: =C8-E8 -> 6 | E8: =CZ!J4 -> 0 | F8: =(C8-E8)/C8*1 -> 1 | G8: =C8-H8 -> 6 | H8: =CZ!J9 -> 0 | I8: =(C8-H8)/C8 -> 1
A9: CW22 | B9: 25/05/2026 - 29/05/2026 | C9: =CZ!M3 -> 5 | D9: =C9-E9 -> 3 | E9: =CZ!M4 -> 2 | F9: =(C9-E9)/C9*1 -> 0.6 | G9: =C9-H9 -> 5 | H9: =CZ!M9 -> 0 | I9: =(C9-H9)/C9 -> 1
A11: Singapore
A12: CW19 | B12: 04/05/2026 - 08/05/2026 | C12: =SG!C3 -> 61 | D12: =C12-E12 -> 39 | E12: =SG!C4 -> 22 | F12: =(C12-E12)/C12*1 -> 0.63934426 | G12: =C12-H12 -> 61 | H12: =SG!C9 -> 0 | I12: =(C12-H12)/C12 -> 1
A13: CW20 | B13: 11/05/2026 - 15/05/2026 | C13: =SG!F3 -> 58 | D13: =C13-E13 -> 36 | E13: =SG!F4 -> 22 | F13: =(C13-E13)/C13*1 -> 0.62068966 | G13: =C13-H13 -> 58 | H13: =SG!F9 -> 0 | I13: =(C13-H13)/C13 -> 1
A14: CW21 | B14: 18/05/2026 - 22/05/2026 | C14: =SG!I3 -> 54 | D14: =C14-E14 -> 33 | E14: =SG!I4 -> 21 | F14: =(C14-E14)/C14*1 -> 0.61111111 | G14: =C14-H14 -> 54 | H14: =SG!I9 -> 0 | I14: =(C14-H14)/C14 -> 1
A15: CW22 | B15: 25/05/2026 - 29/05/2026 | C15: =SG!L3 -> 46 | D15: =C15-E15 -> 33 | E15: =SG!L4 -> 13 | F15: =(C15-E15)/C15*1 -> 0.7173913 | G15: =C15-H15 -> 46 | H15: =SG!L9 -> 0 | I15: =(C15-H15)/C15 -> 1
A17: Malaysia
A18: CW19 | B18: 04/05/2026 - 08/05/2026 | C18: =MY!C3 -> 167 | D18: =C18-E18 -> 163 | E18: =MY!C4 -> 4 | F18: =(C18-E18)/C18*1 -> 0.9760479 | G18: =C18-H18 -> 167 | H18: =MY!C9 -> 0 | I18: =(C18-H18)/C18 -> 1
A19: CW20 | B19: 11/05/2026 - 15/05/2026 | C19: =MY!F3 -> 171 | D19: =C19-E19 -> 166 | E19: =MY!F4 -> 5 | F19: =(C19-E19)/C19*1 -> 0.97076023 | G19: =C19-H19 -> 171 | H19: =MY!F9 -> 0 | I19: =(C19-H19)/C19 -> 1
A20: CW21 | B20: 18/05/2026 - 22/05/2026 | C20: =MY!I3 -> 169 | D20: =C20-E20 -> 163 | E20: =MY!I4 -> 6 | F20: =(C20-E20)/C20*1 -> 0.96449704 | G20: =C20-H20 -> 168 | H20: =MY!I9 -> 1 | I20: =(C20-H20)/C20 -> 0.99408284
A21: CW22 | B21: 25/05/2026 - 29/05/2026 | C21: =MY!L3 -> 106 | D21: =C21-E21 -> 64 | E21: =MY!L4 -> 42 | F21: =(C21-E21)/C21*1 -> 0.60377358 | G21: =C21-H21 -> 106 | H21: =MY!L9 -> 0 | I21: =(C21-H21)/C21 -> 1
A23: Thailand
A24: CW19 | B24: 04/05/2026 - 08/05/2026 | C24: =THAI!C4 -> 10 | D24: =C24-E24 -> 6 | E24: =THAI!C5 -> 4 | F24: =(C24-E24)/C24*1 -> 0.6 | G24: =C24-H24 -> 10 | H24: =THAI!C10 -> 0 | I24: =(C24-H24)/C24 -> 1
A25: CW20 | B25: 11/05/2026 - 15/05/2026 | C25: =THAI!F4 -> 8 | D25: =C25-E25 -> 5 | E25: =THAI!F5 -> 3 | F25: =(C25-E25)/C25*1 -> 0.625 | G25: =C25-H25 -> 8 | H25: =THAI!F10 -> 0 | I25: =(C25-H25)/C25 -> 1
A26: CW21 | B26: 18/05/2026 - 22/05/2026 | C26: =THAI!I4 -> 11 | D26: =C26-E26 -> 1 | E26: =THAI!I5 -> 10 | F26: =(C26-E26)/C26*1 -> 0.090909091 | G26: =C26-H26 -> 11 | H26: =THAI!I10 -> 0 | I26: =(C26-H26)/C26 -> 1
A27: CW22 | B27: 25/05/2026 - 29/05/2026 | C27: =THAI!L4 -> 6 | D27: =C27-E27 -> 1 | E27: =THAI!L5 -> 5 | F27: =(C27-E27)/C27*1 -> 0.16666667 | G27: =C27-H27 -> 6 | H27: =THAI!L10 -> 0 | I27: =(C27-H27)/C27 -> 1
A28: Total: | C28: =SUM(C6:C27) -> 890 | D28: =SUM(D6:D27) -> 730 | E28: =SUM(E6:E27) -> 160 | F28: =(C28-E28)/C28 -> 0.82022472 | G28: =SUM(G6:G27) -> 889 | H28: =SUM(H6:H27) -> 1 | I28: =(C28-H28)/C28 -> 0.9988764

Sheet CZ
A1: BMW - CZ Delivery Report | D1: CW 19 | G1: CW 20 | J1: CW 21 | M1: CW 22
C2: KPI Calculation | F2: KPI Calculation | I2: KPI Calculation | L2: KPI Calculation
C3: Total No. of Shipments: | D3: 6 | F3: Total No. of Shipments: | G3: 6 | I3: Total No. of Shipments: | J3: 6 | L3: Total No. of Shipments: | M3: 5
C4: No. of failed deliveries: | D4: 1 | F4: No. of failed deliveries: | G4: 0 | I4: No. of failed deliveries: | J4: 0 | L4: No. of failed deliveries: | M4: 2
C5: Before Investigation: | D5: =(D3-D4)/D3 -> 0.83333333 | F5: Before Investigation: | G5: =(G3-G4)/G3 -> 1 | I5: Before Investigation: | J5: =(J3-J4)/J3 -> 1 | L5: Before Investigation: | M5: =(M3-M4)/M3 -> 0.6
C7: KPI Calculation | F7: KPI Calculation | I7: KPI Calculation | L7: KPI Calculation
C8: Total No. of Shipments: | D8: 6 | F8: Total No. of Shipments: | G8: 6 | I8: Total No. of Shipments: | J8: 6 | L8: Total No. of Shipments: | M8: 5
C9: No. of failed deliveries: | D9: 0 | F9: No. of failed deliveries: | G9: 0 | I9: No. of failed deliveries: | J9: 0 | L9: No. of failed deliveries: | M9: 0
C10: After Investigation: | D10: =(D8-D9)/D8 -> 1 | F10: After Investigation: | G10: =(G8-G9)/G8 -> 1 | I10: After Investigation: | J10: =(J8-J9)/J8 -> 1 | L10: After Investigation: | M10: =(M8-M9)/M8 -> 1
A13: No. | B13: CW | C13: Date | D13: Shipment Type | E13: Truck Number | F13: KPI Deadline | G13: Delivered On | H13: KPI Pass/Fail | I13: Remarks | L13: After Investigation Result
A14: 1 | B14: 19 | C14: 46146 | D14: CZ AM | E14: JSR 6731 | F14: 2000 HRS | G14: 46146.764 | H14: Pass | L14: Pass
A15: 2 | B15: 19 | C15: 46147 | D15: CZ AM | E15: JTJ 3259 | F15: 2000 HRS | G15: 46147.765 | H15: Pass | L15: Pass
A16: 3 | B16: 19 | C16: 46148 | D16: CZ AM | E16: JTJ 3259 | F16: 2000 HRS | G16: 46148.774 | H16: Pass | L16: Pass
A17: 4 | B17: 19 | C17: 46149 | D17: CZ AM | E17: JTJ 3259 | F17: 2000 HRS | G17: 46149.745 | H17: Pass | L17: Pass
A18: 5 | B18: 19 | C18: 46149 | D18: CZ PM | E18: BJM 794 | F18: 2300 HRS | G18: 46150.014 | H18: Fail | I18: TRUCK WAS SELECTED FOR OVERALL CHECKING BY TJ KUPANG CUSTOM OFFICER. | L18: Pass
A19: 6 | B19: 19 | C19: 46150 | D19: CZ AM | E19: JTJ 3259 | F19: 2000 HRS | G19: 46150.829 | H19: Pass | L19: Pass
A20: 7 | B20: 20 | C20: 46153 | D20: CZ AM | E20: JTJ 3259 | F20: 2000 HRS | G20: 46153.806 | H20: Pass | L20: Pass
A21: 8 | B21: 20 | C21: 46154 | D21: CZ AM | E21: JTJ 3259 | F21: 2000 HRS | G21: 46154.77 | H21: Pass | L21: Pass
A22: 9 | B22: 20 | C22: 46155 | D22: CZ AM | E22: JTJ 3259 | F22: 2000 HRS | G22: 46155.754 | H22: Pass | L22: Pass
A23: 10 | B23: 20 | C23: 46156 | D23: CZ AM | E23: VR 3460 | F23: 2000 HRS | G23: 46156.827 | H23: Pass | L23: Pass
A24: 11 | B24: 20 | C24: 46156 | D24: CZ PM | E24: VNB 3619 | F24: 2300 HRS | G24: 46156.897 | H24: Pass | L24: Pass
A25: 12 | B25: 20 | C25: 46157 | D25: CZ AM | E25: JTJ 3259 | F25: 2000 HRS | G25: 46158.77 | H25: Pass | L25: Pass
A26: 13 | B26: 21 | C26: 46160 | D26: CZ AM | E26: JTJ 3259 | F26: 2000 HRS | G26: 46160.784 | H26: Pass | L26: Pass
A27: 14 | B27: 21 | C27: 46161 | D27: CZ AM | E27: JTJ 3259 | F27: 2000 HRS | G27: 46161.758 | H27: Pass | L27: Pass
A28: 15 | B28: 21 | C28: 46162 | D28: CZ AM | E28: JTJ 3259 | F28: 2000 HRS | G28: 46162.787 | H28: Pass | L28: Pass
A29: 16 | B29: 21 | C29: 46163 | D29: CZ AM | E29: JTJ 3259 | F29: 2000 HRS | G29: 46163.767 | H29: Pass | L29: Pass
A30: 17 | B30: 21 | C30: 46163 | D30: CZ PM | E30: VNB 3619 | F30: 2300 HRS | G30: 46163.892 | H30: Pass | L30: Pass
A31: 18 | B31: 21 | C31: 46164 | D31: CZ AM | E31: JTJ 3259 | F31: 2000 HRS | G31: 46164.799 | H31: Pass | L31: Pass
A32: 19 | B32: 22 | C32: 46167 | D32: CZ AM | E32: JYS 7658 | F32: 2000 HRS | G32: 46167.839 | H32: Fail | I32: BMW SYSTEM DOWN LED TO LATE TRUCK OUT FROM PDC. | L32: Pass
A33: 20 | B33: 22 | C33: 46168 | D33: CZ AM | E33: JTJ 3259 | F33: 2000 HRS | G33: 46168.847 | H33: Fail | I33: THERE IS AN ADDITIONAL INVOICE (BRUNEI) AND TU CLOSED AT 3PM. | L33: Pass
A34: 21 | B34: 22 | C34: 46170 | D34: CZ AM | E34: JTJ 3259 | F34: 2000 HRS | G34: 46170.754 | H34: Pass | L34: Pass
A35: 22 | B35: 22 | C35: 46170 | D35: CZ PM | E35: JUY 9157 | F35: 2300 HRS | G35: 46170.864 | H35: Pass | L35: Pass
A36: 23 | B36: 22 | C36: 46171 | D36: CZ AM | E36: JTJ 3259 | F36: 2000 HRS | G36: 46171.765 | H36: Pass | L36: Pass

Sheet SG
A1: BMW - SG Delivery Report | C1: CW 19 | F1: CW 20 | I1: CW 21 | L1: CW 22
B2: KPI Calculation | E2: KPI Calculation | H2: KPI Calculation | K2: KPI Calculation
B3: Total No. of Shipments: | C3: 61 | E3: Total No. of Shipments: | F3: 58 | H3: Total No. of Shipments: | I3: 54 | K3: Total No. of Shipments: | L3: 46
B4: No. of failed deliveries: | C4: 22 | E4: No. of failed deliveries: | F4: 22 | H4: No. of failed deliveries: | I4: 21 | K4: No. of failed deliveries: | L4: 13
B5: Before Investigation: | C5: =(C3-C4)/C3 -> 0.63934426 | E5: Before Investigation: | F5: =(F3-F4)/F3 -> 0.62068966 | H5: Before Investigation: | I5: =(I3-I4)/I3 -> 0.61111111 | K5: Before Investigation: | L5: =(L3-L4)/L3 -> 0.7173913
B7: KPI Calculation | E7: KPI Calculation | H7: KPI Calculation | K7: KPI Calculation
B8: Total No. of Shipments: | C8: 61 | E8: Total No. of Shipments: | F8: 58 | H8: Total No. of Shipments: | I8: 54 | K8: Total No. of Shipments: | L8: 46
B9: No. of failed deliveries: | C9: 0 | E9: No. of failed deliveries: | F9: 0 | H9: No. of failed deliveries: | I9: 0 | K9: No. of failed deliveries: | L9: 0
B10: After Investigation: | C10: =(C8-C9)/C8 -> 1 | E10: After Investigation: | F10: =(F8-F9)/F8 -> 1 | H10: After Investigation: | I10: =(I8-I9)/I8 -> 1 | K10: After Investigation: | L10: =(L8-L9)/L8 -> 1
A12: No. | B12: Shipment Number | C12: CW | D12: SHIPMENT TYPE | E12: Customer Account | F12: Customer Reference | G12: Delivery Location | H12: Consignee Code | I12: Collection Date | J12: KPI Deadline | K12: Delivered On | L12: KPI Pass/Fail | M12: Time In Collection Location | N12: Time Out Collection Location | O12: Time In Delivery Location | P12: Time Out Delivery Location | Q12: Remark for Customer | R12: Customer Route Code | S12: DG | T12: Customer Invoice Number(s) | U12: Country (Delivery Location) | V12: After Investigation Result
A13: 1 | B13: S202605-14793 | C13: 19 | D13: SGAM | E13: BMW | F13: 3015122735 | G13: Performance Motors Ltd 780 | H13: 780 | I13: 46146 | J13: 46146.646 | K13: 46146.631 | L13: Pass | M13: 46146.447 | N13: 46146.475 | O13: 46146.615 | P13: 46146.661 | R13: 01SGD1 | S13: Yes | T13: 8260099228 | U13: SGP | V13: Pass
A14: 2 | B14: S202605-14794 | C14: 19 | D14: SGAM | E14: BMW | F14: 3015122773 | G14: Eurokars Habitat Pte Ltd | H14: 29902 | I14: 46146 | J14: 46146.656 | K14: 46146.647 | L14: Pass | M14: 46146.447 | N14: 46146.475 | O14: 46146.604 | P14: 46146.615 | R14: 01SGD2 | S14: Yes | T14: 8260099229 | U14: SGP | V14: Pass
A15: 3 | B15: S202605-14792 | C15: 19 | D15: SGAM | E15: BMW | F15: 3015122736 | G15: Eurokars Auto Pte Ltd | H15: 51570 | I15: 46146 | J15: 46146.656 | K15: 46146.646 | L15: Pass | M15: 46146.447 | N15: 46146.475 | O15: 46146.604 | P15: 46146.615 | R15: 01SGD2 | S15: Yes | T15: 8260099230 | U15: SGP | V15: Pass
A16: 4 | B16: S202605-14795 | C16: 19 | D16: SGAM | E16: BMW | F16: 3015122774 | G16: Performance Motors Ltd 3244 | H16: 3244 | I16: 46146 | J16: 46146.646 | K16: 46146.623 | L16: Pass | M16: 46146.447 | N16: 46146.475 | O16: 46146.615 | P16: 46146.661 | R16: 01SGD5 | S16: Yes | T16: 8260099231 | U16: SGP | V16: Pass
A17: 5 | B17: S202605-14796 | C17: 19 | D17: SGAM | E17: BMW | F17: 3015122768 | G17: Eurokars Habitat Pte Ltd | H17: 29902 | I17: 46146 | J17: 46146.656 | K17: 46146.647 | L17: Pass | M17: 46146.447 | N17: 46146.475 | O17: 46146.604 | P17: 46146.615 | R17: 01SG02 | S17: No | T17: 8260099232 | U17: SGP | V17: Pass
A18: 6 | B18: S202605-14798 | C18: 19 | D18: SGAM | E18: BMW | F18: 3015122769 | G18: Performance Motors Ltd 780 | H18: 780 | I18: 46146 | J18: 46146.646 | K18: 46146.631 | L18: Pass | M18: 46146.447 | N18: 46146.475 | O18: 46146.615 | P18: 46146.661 | R18: 01SG01 | S18: No | T18: 8260099233 | U18: SGP | V18: Pass
A19: 7 | B19: S202605-14797 | C19: 19 | D19: SGAM | E19: BMW | F19: 3015122790 | G19: Performance Motors Ltd 3244 | H19: 3244 | I19: 46146 | J19: 46146.646 | K19: 46146.623 | L19: Pass | M19: 46146.447 | N19: 46146.475 | O19: 46146.615 | P19: 46146.661 | R19: 01SG05 | S19: No | T19: 8260099234 | U19: SGP | V19: Pass
A20: 8 | B20: S202605-14837 | C20: 19 | D20: SGPM | E20: BMW | F20: 3015123986 | G20: Eurokars Habitat Pte Ltd | H20: 29902 | I20: 46146 | J20: 46146.969 | K20: 46146.908 | L20: Pass | N20: 46146.752 | O20: 46146.903 | P20: 46146.913 | R20: 02SG02 | S20: No | T20: 8260099294 | U20: SGP | V20: Pass
A21: 9 | B21: S202605-14835 | C21: 19 | D21: SGPM | E21: BMW | F21: 3015123987 | G21: Performance Motors Ltd 780 | H21: 780 | I21: 46146 | J21: 46146.958 | K21: 46146.922 | L21: Pass | N21: 46146.752 | O21: 46146.914 | P21: 46146.925 | R21: 02SG01 | S21: No | T21: 8260099295 | U21: SGP | V21: Pass
A22: 10 | B22: S202605-14836 | C22: 19 | D22: SGPM | E22: BMW | F22: 3015123990 | G22: Eurokars Auto Pte Ltd | H22: 51570 | I22: 46146 | J22: 46146.969 | K22: 46146.911 | L22: Pass | N22: 46146.752 | O22: 46146.903 | P22: 46146.913 | R22: 02SG02 | S22: No | T22: 8260099296 | U22: SGP | V22: Pass
A23: 11 | B23: S202605-14848 | C23: 19 | D23: SGAM | E23: BMW | F23: 3015125684 | G23: Performance Motors Ltd 780 | H23: 780 | I23: 46147 | J23: 46147.646 | K23: 46147.603 | L23: Pass | O23: 46147.592 | P23: 46147.615 | R23: 01SGD1 | S23: Yes | T23: 8260099302 | U23: SGP | V23: Pass
A24: 12 | B24: S202605-14847 | C24: 19 | D24: SGAM | E24: BMW | F24: 3015125795 | G24: Eng Soon Auto Pte Ltd | H24: 53495 | I24: 46147 | J24: 46147.719 | K24: 46147.678 | L24: Pass | N24: 46147.478 | O24: 46147.638 | P24: 46147.675 | R24: 01SGD3 | S24: Yes | T24: 8260099303 | U24: SGP | V24: Pass
A25: 13 | B25: S202605-14850 | C25: 19 | D25: SGAM | E25: BMW | F25: 3015125796 | G25: Performance Motors Ltd 3244 | H25: 3244 | I25: 46147 | J25: 46147.646 | K25: 46147.598 | L25: Pass | O25: 46147.592 | P25: 46147.615 | R25: 01SGD5 | S25: Yes | T25: 8260099304 | U25: SGP | V25: Pass
A26: 14 | B26: S202605-14849 | C26: 19 | D26: SGAM | E26: BMW | F26: 3015125685 | G26: Golden Link Auto Pte Ltd | H26: 53722 | I26: 46147 | J26: 46147.74 | K26: 46147.657 | L26: Pass | O26: 46147.653 | P26: 46147.656 | R26: 01SGD3 | S26: Yes | T26: 8260099305 | U26: SGP | V26: Pass
A27: 15 | B27: S202605-14842 | C27: 19 | D27: SGAM | E27: BMW | F27: 3015125797 | G27: Performance Motors Ltd 3244 | H27: 3244 | I27: 46147 | J27: 46147.646 | K27: 46147.598 | L27: Pass | O27: 46147.592 | P27: 46147.615 | R27: 01SG05 | S27: No | T27: 8260099306 | U27: SGP | V27: Pass
A28: 16 | B28: S202605-14845 | C28: 19 | D28: SGAM | E28: BMW | F28: 3015125798 | G28: Golden Link Auto Pte Ltd | H28: 53722 | I28: 46147 | J28: 46147.74 | K28: 46147.657 | L28: Pass | O28: 46147.653 | P28: 46147.656 | R28: 01SG03 | S28: No | T28: 8260099307 | U28: SGP | V28: Pass
A29: 17 | B29: S202605-14844 | C29: 19 | D29: SGAM | E29: BMW | F29: 3015125810 | G29: Eurokars Habitat Pte Ltd | H29: 29902 | I29: 46147 | J29: 46147.656 | K29: 46147.624 | L29: Pass | O29: 46147.619 | P29: 46147.631 | R29: 01SG02 | S29: No | T29: 8260099308 | U29: SGP | V29: Pass
A30: 18 | B30: S202605-14843 | C30: 19 | D30: SGAM | E30: BMW | F30: 3015125811 | G30: Performance Motors Ltd 780 | H30: 780 | I30: 46147 | J30: 46147.646 | K30: 46147.603 | L30: Pass | O30: 46147.592 | P30: 46147.615 | R30: 01SG01 | S30: No | T30: 8260099309 | U30: SGP | V30: Pass
A31: 19 | B31: S202605-14841 | C31: 19 | D31: SGAM | E31: BMW | F31: 3015125812 | G31: Eurokars Auto Pte Ltd | H31: 51570 | I31: 46147 | J31: 46147.656 | K31: 46147.625 | L31: Pass | O31: 46147.619 | P31: 46147.631 | R31: 01SG02 | S31: No | T31: 8260099310 | U31: SGP | V31: Pass
A32: 20 | B32: S202605-14846 | C32: 19 | D32: SGAM | E32: BMW | F32: 3015125799 | G32: Eng Soon Auto Pte Ltd | H32: 53495 | I32: 46147 | J32: 46147.719 | K32: 46147.678 | L32: Pass | N32: 46147.478 | O32: 46147.638 | P32: 46147.675 | R32: 01SG03 | S32: No | T32: 8260099311 | U32: SGP | V32: Pass
A33: 21 | B33: S202605-14885 | C33: 19 | D33: SGPM | E33: BMW | F33: 3015127087 | G33: Eurokars Habitat Pte Ltd | H33: 29902 | I33: 46147 | J33: 46147.969 | K33: 46147.955 | L33: Pass | N33: 46147.759 | O33: 46147.946 | P33: 46147.957 | R33: 02SG02 | S33: No | T33: 8260099361 | U33: SGP | V33: Pass
A34: 22 | B34: S202605-14884 | C34: 19 | D34: SGPM | E34: BMW | F34: 3015127088 | G34: Eurokars Auto Pte Ltd | H34: 51570 | I34: 46147 | J34: 46147.969 | K34: 46147.953 | L34: Pass | N34: 46147.759 | O34: 46147.946 | P34: 46147.957 | R34: 02SG02 | S34: No | T34: 8260099362 | U34: SGP | V34: Pass
A35: 23 | B35: S202605-14886 | C35: 19 | D35: SGPM | E35: BMW | F35: 3015127094 | G35: Performance Motors Ltd 780 | H35: 780 | I35: 46147 | J35: 46147.958 | K35: 46147.971 | L35: Pass | N35: 46147.759 | O35: 46147.958 | P35: 46147.975 | R35: 02SG01 | S35: No | T35: 8260099363 | U35: SGP | V35: Pass
A36: 24 | B36: S202605-14894 | C36: 19 | D36: SGAM | E36: BMW | F36: 3015125794 | G36: Performance Motors Ltd 780 | H36: 780 | I36: 46148 | J36: 46148.646 | K36: 46148.633 | L36: Pass | R36: 01SGD1 | S36: Yes | T36: 8260099301 | U36: SGP | V36: Pass
A37: 25 | B37: S202605-14891 | C37: 19 | D37: SGAM | E37: BMW | F37: 3015128910 | G37: Performance Motors Ltd 780 | H37: 780 | I37: 46148 | J37: 46148.646 | K37: 46148.638 | L37: Pass | N37: 46148.484 | O37: 46148.633 | P37: 46148.657 | R37: 01SGD1 | S37: Yes | T37: 8260099368 | U37: SGP | V37: Pass
A38: 26 | B38: S202605-14890 | C38: 19 | D38: SGAM | E38: BMW | F38: 3015128902 | G38: Eurokars Habitat Pte Ltd | H38: 29902 | I38: 46148 | J38: 46148.656 | K38: 46148.668 | L38: Fail | N38: 46148.484 | O38: 46148.661 | P38: 46148.672 | Q38: TRAFFIC CONGESTION AT BOTH CHECKOINTS DUE TO AKPS PROCEDURE & RANDOM CHECKING DONE BY ICA LED TO BUILD UP LONG QUEUE FOR CUSTOM CLEARANCE PROCESS. | R38: 01SGD2 | S38: Yes | T38: 8260099369 | U38: SGP | V38: Pass
A39: 27 | B39: S202605-14892 | C39: 19 | D39: SGAM | E39: BMW | F39: 3015128863 | G39: Eurokars Auto Pte Ltd | H39: 51570 | I39: 46148 | J39: 46148.656 | K39: 46148.665 | L39: Fail | N39: 46148.484 | O39: 46148.661 | P39: 46148.672 | Q39: TRAFFIC CONGESTION AT BOTH CHECKOINTS DUE TO AKPS PROCEDURE & RANDOM CHECKING DONE BY ICA LED TO BUILD UP LONG QUEUE FOR CUSTOM CLEARANCE PROCESS. | R39: 01SGD2 | S39: Yes | T39: 8260099370 | U39: SGP | V39: Pass
A40: 28 | B40: S202605-14893 | C40: 19 | D40: SGAM | E40: BMW | F40: 3015128828 | G40: Performance Motors Ltd 3244 | H40: 3244 | I40: 46148 | J40: 46148.646 | K40: 46148.64 | L40: Pass | N40: 46148.484 | O40: 46148.633 | P40: 46148.657 | R40: 01SGD5 | S40: Yes | T40: 8260099371 | U40: SGP | V40: Pass
A41: 29 | B41: S202605-14896 | C41: 19 | D41: SGAM | E41: BMW | F41: 3015128921 | G41: Performance Motors Ltd 3244 | H41: 3244 | I41: 46148 | J41: 46148.646 | K41: 46148.64 | L41: Pass | N41: 46148.484 | O41: 46148.633 | P41: 46148.657 | R41: 01SG05 | S41: No | T41: 8260099372 | U41: SGP | V41: Pass
A42: 30 | B42: S202605-14895 | C42: 19 | D42: SGAM | E42: BMW | F42: 3015128922 | G42: Eurokars Habitat Pte Ltd | H42: 29902 | I42: 46148 | J42: 46148.656 | K42: 46148.668 | L42: Fail | N42: 46148.484 | O42: 46148.661 | P42: 46148.672 | Q42: TRAFFIC CONGESTION AT BOTH CHECKOINTS DUE TO AKPS PROCEDURE & RANDOM CHECKING DONE BY ICA LED TO BUILD UP LONG QUEUE FOR CUSTOM CLEARANCE PROCESS. | R42: 01SG02 | S42: No | T42: 8260099373 | U42: SGP | V42: Pass
...

Sheet MY
A1: BMW - MY Delivery Report | C1: CW 19 | F1: CW 20 | I1: CW 21 | L1: CW 22
B2: KPI Calculation | E2: KPI Calculation | H2: KPI Calculation | K2: KPI Calculation
B3: Total No. of Shipments: | C3: 167 | E3: Total No. of Shipments: | F3: 171 | H3: Total No. of Shipments: | I3: 169 | K3: Total No. of Shipments: | L3: 106
B4: No. of failed deliveries: | C4: 4 | E4: No. of failed deliveries: | F4: 5 | H4: No. of failed deliveries: | I4: 6 | K4: No. of failed deliveries: | L4: 42
B5: Before Investigation: | C5: =(C3-C4)/C3 -> 0.9760479 | E5: Before Investigation: | F5: =(F3-F4)/F3 -> 0.97076023 | H5: Before Investigation: | I5: =(I3-I4)/I3 -> 0.96449704 | K5: Before Investigation: | L5: =(L3-L4)/L3 -> 0.60377358
B7: KPI Calculation | E7: KPI Calculation | H7: KPI Calculation | K7: KPI Calculation
B8: Total No. of Shipments: | C8: 167 | E8: Total No. of Shipments: | F8: 171 | H8: Total No. of Shipments: | I8: 169 | K8: Total No. of Shipments: | L8: 106
B9: No. of failed deliveries: | C9: 0 | E9: No. of failed deliveries: | F9: 0 | H9: No. of failed deliveries: | I9: 1 | K9: No. of failed deliveries: | L9: 0
B10: After Investigation: | C10: =(C8-C9)/C8 -> 1 | E10: After Investigation: | F10: =(F8-F9)/F8 -> 1 | H10: After Investigation: | I10: =(I8-I9)/I8 -> 0.99408284 | K10: After Investigation: | L10: =(L8-L9)/L8 -> 1
A12: No. | B12: Shipment Number | C12: CW | D12: SHIPMENT TYPE | E12: Customer Account | F12: Customer Reference | G12: Delivery Location | H12: Consignee Code | I12: Collection Date | J12: KPI Deadline | K12: Delivered On | L12: KPI Pass/Fail | M12: Time In Collection Location | N12: Time Out Collection Location | O12: Time In Delivery Location | P12: Time Out Delivery Location | Q12: Remark for Customer | R12: Customer Route Code | S12: DG | T12: Customer Invoice Number(s) | U12: Country (Delivery Location) | V12: After Investigation Result
A13: 1 | B13: S202605-14807 | C13: 19 | D13: MY | E13: BMW | F13: 3015123529 | G13: Millennium Welt, K.Terengganu | H13: 53236 | I13: 46146 | J13: 46147.875 | K13: 46147.485 | L13: Pass | O13: 46147.479 | P13: 46147.487 | R13: 01MY14 | S13: No | T13: 8260099256 | U13: MYS | V13: Pass
A14: 2 | B14: S202605-14810 | C14: 19 | D14: MY | E14: BMW | F14: 3015123587 | G14: SDM Sg Tengah | H14: 27307 | I14: 46146 | J14: 46147.656 | K14: 46147.503 | L14: Pass | O14: 46147.497 | P14: 46147.507 | R14: 01MY04 | S14: No | T14: 8260099257 | U14: MYS | V14: Pass
A15: 3 | B15: S202605-14809 | C15: 19 | D15: MY | E15: BMW | F15: 3015123589 | G15: Tian Siang Jln Prai (Butterworth) | H15: 35787 | I15: 46146 | J15: 46147.604 | K15: 46147.497 | L15: Pass | O15: 46147.485 | P15: 46147.503 | R15: 01MY04 | S15: No | T15: 8260099258 | U15: MYS | V15: Pass
A16: 4 | B16: S202605-14808 | C16: 19 | D16: MY | E16: BMW | F16: 3015123592 | G16: Lee Motors Alor Star | H16: 27240 | I16: 46146 | J16: 46147.708 | K16: 46147.52 | L16: Pass | O16: 46147.516 | P16: 46147.523 | R16: 01MY08 | S16: No | T16: 8260099259 | U16: MYS | V16: Pass
A17: 5 | B17: S202605-14801 | C17: 19 | D17: MY | E17: BMW | F17: 3015123629 | G17: Millenium Kuantan 43638 | H17: 43638 | I17: 46146 | J17: 46147.458 | K17: 46147.378 | L17: Pass | M17: 46146.723 | N17: 46146.736 | O17: 46147.371 | P17: 46147.38 | R17: 01MY07 | S17: No | T17: 8260099260 | U17: MYS | V17: Pass
A18: 6 | B18: S202605-14800 | C18: 19 | D18: MY | E18: BMW | F18: 3015123650 | G18: Seong Hoe, Semabok | H18: 29479 | I18: 46146 | J18: 46147.521 | K18: 46147.429 | L18: Pass | O18: 46147.426 | P18: 46147.434 | R18: 01MY13 | S18: No | T18: 8260099261 | U18: MYS | V18: Pass
A19: 7 | B19: S202605-14803 | C19: 19 | D19: MY | E19: BMW | F19: 3015123653 | G19: Millennium Welt, Seremban 46274 | H19: 46274 | I19: 46146 | J19: 46147.438 | K19: 46147.345 | L19: Pass | O19: 46147.294 | P19: 46147.365 | R19: 01MY10 | S19: No | T19: 8260099262 | U19: MYS | V19: Pass
A20: 8 | B20: S202605-14804 | C20: 19 | D20: MY | E20: BMW | F20: 3015123654 | G20: Millenium Kuantan 47057 | H20: 47057 | I20: 46146 | J20: 46147.458 | K20: 46147.378 | L20: Pass | M20: 46146.723 | N20: 46146.736 | O20: 46147.371 | P20: 46147.381 | R20: 01MY07 | S20: No | T20: 8260099263 | U20: MYS | V20: Pass
A21: 9 | B21: S202605-14805 | C21: 19 | D21: MY | E21: BMW | F21: 3015123655 | G21: Performance Motor Puchong | H21: 53929 | I21: 46146 | J21: 46147.375 | K21: 46147.288 | L21: Pass | O21: 46147.281 | P21: 46147.29 | R21: 01MY03 | S21: No | T21: 8260099264 | U21: MYS | V21: Pass
A22: 10 | B22: S202605-14802 | C22: 19 | D22: MY | E22: BMW | F22: 3015123656 | G22: SDM Penang Jln Anson | H22: 27306 | I22: 46146 | J22: 46147.625 | K22: 46147.503 | L22: Pass | O22: 46147.497 | P22: 46147.507 | R22: 01MY04 | S22: No | T22: 8260099265 | U22: MYS | V22: Pass
A23: 11 | B23: S202605-14814 | C23: 19 | D23: MY | E23: BMW | F23: 3015123660 | G23: SDM Tebrau 49327 | H23: 49327 | I23: 46146 | J23: 46147.448 | K23: 46147.4 | L23: Pass | N23: 46146.736 | O23: 46147.391 | P23: 46147.401 | R23: 01MY12 | S23: No | T23: 8260099266 | U23: MYS | V23: Pass
A24: 12 | B24: S202605-14813 | C24: 19 | D24: MY | E24: BMW | F24: 3015123661 | G24: SDM Tebrau 49330 | H24: 49330 | I24: 46146 | J24: 46147.448 | K24: 46147.399 | L24: Pass | M24: 46146.723 | N24: 46146.736 | O24: 46147.391 | P24: 46147.401 | R24: 01MY12 | S24: No | T24: 8260099267 | U24: MYS | V24: Pass
A25: 13 | B25: S202605-14811 | C25: 19 | D25: MY | E25: BMW | F25: 3015123662 | G25: Performance Kepong | H25: 53931 | I25: 46146 | J25: 46147.354 | K25: 46147.077 | L25: Pass | O25: 46147.069 | P25: 46147.106 | R25: 01MY03 | S25: No | T25: 8260099268 | U25: MYS | V25: Pass
A26: 14 | B26: S202605-14812 | C26: 19 | D26: MY | E26: BMW | F26: 3015123663 | G26: SDM ARA Damansara 27303 | H26: 27303 | I26: 46146 | J26: 46147.354 | K26: 46147.351 | L26: Pass | O26: 46147.294 | P26: 46147.354 | R26: 01MY03 | S26: No | T26: 8260099269 | U26: MYS | V26: Pass
A27: 15 | B27: S202605-14806 | C27: 19 | D27: MY | E27: BMW | F27: 3015123670 | G27: Sime Darby Auto Bavaria Sdn. Bhd (Sg.Besi) | H27: 52770 | I27: 46146 | J27: 46147.458 | K27: 46147.349 | L27: Pass | R27: 01MY03 | S27: No | T27: 8260099270 | U27: MYS | V27: Pass
A28: 16 | B28: S202605-14815 | C28: 19 | D28: MY | E28: BMW | F28: 3015123671 | G28: Wheelcorp Premium - Setia Alam | H28: 54775 | I28: 46146 | J28: 46147.5 | K28: 46147.424 | L28: Pass | O28: 46147.421 | P28: 46147.426 | R28: 01MY03 | S28: No | T28: 8260099271 | U28: MYS | V28: Pass
A29: 17 | B29: S202605-14822 | C29: 19 | D29: MY | E29: BMW | F29: 3015123673 | G29: SDM Body & Paint | H29: 52292 | I29: 46146 | J29: 46147.688 | K29: 46147.486 | L29: Pass | O29: 46147.485 | P29: 46147.491 | R29: 01MY04 | S29: No | T29: 8260099272 | U29: MYS | V29: Pass
A30: 18 | B30: S202605-14817 | C30: 19 | D30: MY | E30: BMW | F30: 3015123675 | G30: King Hup Shah Alam ( Rimbunan Kuasa Sdn Bhd) | H30: 46678 | I30: 46146 | J30: 46147.427 | K30: 46147.397 | L30: Pass | O30: 46147.382 | P30: 46147.402 | R30: 01MY03 | S30: No | T30: 8260099273 | U30: MYS | V30: Pass
A31: 19 | B31: S202605-14821 | C31: 19 | D31: MY | E31: BMW | F31: 3015123676 | G31: SDM ARA Damansara 25329 | H31: 25329 | I31: 46146 | J31: 46147.354 | K31: 46147.35 | L31: Pass | O31: 46147.294 | P31: 46147.354 | R31: 01MY03 | S31: No | T31: 8260099274 | U31: MYS | V31: Pass
A32: 20 | B32: S202605-14816 | C32: 19 | D32: MY | E32: BMW | F32: 3015123680 | G32: Chear Motorrad | H32: 36820 | I32: 46146 | J32: 46147.469 | K32: 46147.394 | L32: Pass | O32: 46147.388 | P32: 46147.397 | R32: 01MY03 | S32: No | T32: 8260099275 | U32: MYS | V32: Pass
A33: 21 | B33: S202605-14819 | C33: 19 | D33: MY | E33: BMW | F33: 3015123682 | G33: SDM CSL | H33: 49902 | I33: 46146 | J33: 46147.479 | K33: 46147.343 | L33: Pass | O33: 46147.318 | P33: 46147.344 | R33: 01MY03 | S33: No | T33: 8260099276 | U33: MYS | V33: Pass
A34: 22 | B34: S202605-14820 | C34: 19 | D34: MY | E34: BMW | F34: 3015123683 | G34: Millenium Batu Pahat | H34: 41879 | I34: 46146 | J34: 46147.656 | K34: 46147.494 | L34: Pass | M34: 46146.723 | N34: 46146.736 | O34: 46147.493 | P34: 46147.502 | R34: 01MY11 | S34: No | T34: 8260099277 | U34: MYS | V34: Pass
A35: 23 | B35: S202605-14818 | C35: 19 | D35: MY | E35: BMW | F35: 3015123684 | G35: Bavarian Auto, Segambut | H35: 46677 | I35: 46146 | J35: 46147.479 | K35: 46147.403 | L35: Pass | O35: 46147.37 | P35: 46147.405 | R35: 01MY03 | S35: No | T35: 8260099278 | U35: MYS | V35: Pass
A36: 24 | B36: S202605-14828 | C36: 19 | D36: MY | E36: BMW | F36: 3015123593 | G36: Tian Siang Ipoh 30484 | H36: 30484 | I36: 46146 | J36: 46147.469 | K36: 46147.388 | L36: Pass | O36: 46147.383 | P36: 46147.393 | R36: 01MY05 | S36: No | T36: 8260099281 | U36: MYS | V36: Pass
A37: 25 | B37: S202605-14826 | C37: 19 | D37: MY | E37: BMW | F37: 3015123657 | G37: SDM Skudai | H37: 25435 | I37: 46146 | J37: 46147.396 | K37: 46147.373 | L37: Pass | M37: 46146.723 | N37: 46146.736 | O37: 46147.368 | P37: 46147.374 | R37: 01MY12 | S37: No | T37: 8260099282 | U37: MYS | V37: Pass
A38: 26 | B38: S202605-14830 | C38: 19 | D38: MY | E38: BMW | F38: 3015123664 | G38: SDM Tun Razak | H38: 35782 | I38: 46146 | J38: 46147.438 | K38: 46147.315 | L38: Pass | R38: 01MY03 | S38: No | T38: 8260099283 | U38: MYS | V38: Pass
A39: 27 | B39: S202605-14833 | C39: 19 | D39: MY | E39: BMW | F39: 3015123677 | G39: SDM Balakong | H39: 27304 | I39: 46146 | J39: 46147.396 | K39: 46147.367 | L39: Pass | R39: 01MY03 | S39: No | T39: 8260099284 | U39: MYS | V39: Pass
A40: 28 | B40: S202605-14823 | C40: 19 | D40: MY | E40: BMW | F40: 3015123686 | G40: SDM Sg Pinang | H40: 49903 | I40: 46146 | J40: 46147.667 | K40: 46147.471 | L40: Pass | O40: 46147.47 | P40: 46147.483 | R40: 01MY04 | S40: No | T40: 8260099285 | U40: MYS | V40: Pass
A41: 29 | B41: S202605-14831 | C41: 19 | D41: MY | E41: BMW | F41: 3015123687 | G41: Millennium Welt, Seremban 39488 | H41: 39488 | I41: 46146 | J41: 46147.438 | K41: 46147.344 | L41: Pass | O41: 46147.294 | P41: 46147.365 | R41: 01MY10 | S41: No | T41: 8260099286 | U41: MYS | V41: Pass
A42: 30 | B42: S202605-14825 | C42: 19 | D42: MY | E42: BMW | F42: 3015123688 | G42: Quill Automobile, P.Jaya | H42: 33873 | I42: 46146 | J42: 46147.427 | K42: 46147.267 | L42: Pass | O42: 46147.257 | P42: 46147.269 | R42: 01MY03 | S42: No | T42: 8260099287 | U42: MYS | V42: Pass
...

Sheet THAI
A1: BMW Thailand Delivery Report
C2: CW 19 | F2: CW 20 | I2: CW 21 | L2: CW 22
B3: KPI Calculation | E3: KPI Calculation | H3: KPI Calculation | K3: KPI Calculation
B4: Total No. of Shipments: | C4: 10 | E4: Total No. of Shipments: | F4: 8 | H4: Total No. of Shipments: | I4: 11 | K4: Total No. of Shipments: | L4: 6
B5: No. of failed deliveries: | C5: 4 | E5: No. of failed deliveries: | F5: 3 | H5: No. of failed deliveries: | I5: 10 | K5: No. of failed deliveries: | L5: 5
B6: Before Investigation: | C6: =(C4-C5)/C4 -> 0.6 | E6: Before Investigation: | F6: =(F4-F5)/F4 -> 0.625 | H6: Before Investigation: | I6: =(I4-I5)/I4 -> 0.090909091 | K6: Before Investigation: | L6: =(L4-L5)/L4 -> 0.16666667
B8: KPI Calculation | E8: KPI Calculation | H8: KPI Calculation | K8: KPI Calculation
B9: Total No. of Shipments: | C9: 10 | E9: Total No. of Shipments: | F9: 8 | H9: Total No. of Shipments: | I9: 11 | K9: Total No. of Shipments: | L9: 6
B10: No. of failed deliveries: | C10: 0 | E10: No. of failed deliveries: | F10: 0 | H10: No. of failed deliveries: | I10: 0 | K10: No. of failed deliveries: | L10: 0
B11: After Investigation: | C11: =(C9-C10)/C9 -> 1 | E11: After Investigation: | F11: =(F9-F10)/F9 -> 1 | H11: After Investigation: | I11: =(I9-I10)/I9 -> 1 | K11: After Investigation: | L11: =(L9-L10)/L9 -> 1
A13: No. | B13: Collection Date | C13: CW | D13: SHIPMENT TYPE | E13: Truck No. | F13: Container No. | G13: LG No. | H13: Shipment No. | I13: BMW Invoice No. | J13: No. of Packages | K13: Gross Weight (KG) | L13: Volume (M3) | M13: Delivered On | N13: Delivery Time | O13: KPI Pass/Fail | P13: Remarks | Q13: After Investigation Result
A14: 1 | B14: 46147 | C14: 19 | D14: TH | E14: KFE 2855 | F14: EHUU5550230 | G14: 1002832818 | H14: 3015125792 | I14: 8260099298 | J14: 117 | K14: 6927.38 | L14: 56.014 | M14: 46149 | N14: 0.44930556 | O14: Pass | Q14: Pass
A15: 2 | B15: 46147 | C15: 19 | D15: TH | E15: KFD 8755 | F15: FTMU5550195 | G15: 1002832819 | H15: 3015125793 | I15: 8260099299 | J15: 99 | K15: 9551.82 | L15: 67.871 | M15: 46158 | N15: 0.44305556 | O15: Fail | P15: DETAINED AT SADAO DUE TO 1 ITEM (288) REQUIRE TH TISI IMPORT PERMIT. 15/05/2026 CROSS BORDER. | Q15: Pass
A16: 3 | B16: 46147 | C16: 19 | D16: TH | E16: KFB 5755 | F16: EHUU5550473 | G16: 1002832820 | H16: 3015125682 | I16: 8260099300 | J16: 90 | K16: 4948.91 | L16: 62.38 | M16: 46149 | N16: 0.62569444 | O16: Pass | Q16: Pass
A17: 4 | B17: 46148 | C17: 19 | D17: TH | E17: KEG 7055 | F17: FTTU5550652 | G17: 1002832821 | H17: 3015128836 | I17: 8260099364 | J17: 51 | K17: 3791.92 | L17: 61.046 | M17: 46150 | N17: 0.625 | O17: Pass | Q17: Pass
A18: 5 | B18: 46148 | C18: 19 | D18: TH | E18: KEA 5055 | F18: EHUU5550137 | G18: 1002832822 | H18: 3015128837 | I18: 8260099365 | J18: 66 | K18: 5045.8 | L18: 59.411 | M18: 46150 | N18: 0.069444444 | O18: Pass | Q18: Pass
A19: 6 | B19: 46148 | C19: 19 | D19: TH | E19: KFE 2955 | F19: CICU2627784 | G19: 1002832823 | H19: 3015128838 | I19: 8260099366 | J19: 76 | K19: 7089.62 | L19: 66.724 | M19: 46150 | N19: 0.38541667 | O19: Pass | Q19: Pass
A20: 7 | B20: 46149 | C20: 19 | D20: TH | E20: BJQ 6055 | F20: EHUU5550385 | G20: 1002832824 | H20: 3015131964 | I20: 8260099442 | J20: 111 | K20: 6249.01 | L20: 62.608 | M20: 46162 | N20: 0.575 | O20: Fail | P20: DETAINED AT PDC DUE TO PULLED OUT THE WRONG CONTAINER (EHUU5550061). 15/05/2026 TRUCK OUT FROM PDC. 19/05 : CROSS SADAO | Q20: Pass
A21: 8 | B21: 46149 | C21: 19 | D21: TH | E21: KEL 2055 | F21: EHUU5550061 | G21: 1002832825 | H21: 3015131983 | I21: 8260099443 | J21: 108 | K21: 6725.86 | L21: 61.943 | M21: 46151 | N21: 0.58333333 | O21: Pass | P21: 2 ITEMS (160 & 177) REQUIRE TH TISI IMPORT PERMIT HOWEVER, PULL OUT THE WRONG CONTAINER (EHUU5550385). | Q21: Pass
A22: 9 | B22: 46150 | C22: 19 | D22: TH | E22: KFE 2855 | F22: FTTU5550658 | G22: 1002832828 | H22: 3015135013 | I22: 8260099521 | J22: 77 | K22: 5419.64 | L22: 62.723 | M22: 46154 | N22: 0.68541667 | O22: Fail | P22: INSUFFICIENT FUNDS. CLEARANCE WAS DONE ON MONDAY AND DELIVERY WAS ARRANGED ON TUESDAY. DEALER CLOSE ON SUNDAY. | Q22: Pass
A23: 10 | B23: 46150 | C23: 19 | D23: TH | I23: 8260099522 | J23: 3 | K23: 102 | Q23: Pass
A24: 11 | B24: 46150 | C24: 19 | D24: TH | E24: KEJ 9755 | F24: EHUU5550413 | G24: 1002832826 | H24: 3015134968 | I24: 8260099523 | J24: 82 | K24: 5169.16 | L24: 53.767 | M24: 46154 | N24: 0.48402778 | O24: Fail | P24: INSUFFICIENT FUNDS. CLEARANCE WAS DONE ON MONDAY AND DELIVERY WAS ARRANGED ON TUESDAY. DEALER CLOSE ON SUNDAY. | Q24: Pass
A25: 12 | B25: 46153 | C25: 20 | D25: TH | E25: KFH 8655 | F25: FKTT5550641 | G25: 1002832831 | H25: 3015138337 | I25: 8260099592 | J25: 76 | K25: 5513.16 | L25: 61.44 | M25: 46155 | N25: 0.45138889 | O25: Pass | Q25: Pass
A26: 13 | B26: 46154 | C26: 20 | D26: TH | E26: KFE 2855 | F26: KLNU5000380 | G26: 1002832829 | H26: 3015141356 | I26: 8260099666 | J26: 83 | K26: 7483.24 | L26: 59.637 | M26: 46156 | N26: 0.45833333 | O26: Pass | Q26: Pass
A27: 14 | B27: 46155 | C27: 20 | D27: TH | E27: KDW 5755 | F27: EHUU5550383 | G27: 1002832832 | H27: 3015144347 | I27: 8260099738 | J27: 86 | K27: 4400.12 | L27: 59.411 | M27: 46157 | N27: 0.20833333 | O27: Pass | Q27: Pass
A28: 15 | B28: 46155 | C28: 20 | D28: TH | I28: 8260099739 | J28: 2
A29: 16 | B29: 46155 | C29: 20 | D29: TH | E29: KEJ 9755 | F29: EHUU5550516 | G29: 1002832830 | H29: 3015144480 | I29: 8260099740 | J29: 73 | K29: 3635.6 | L29: 56.888 | M29: 46164 | N29: 0.5 | O29: Fail | P29: DETAINED AT PDC DUE TO 1 ITEM (80) REQUIRE TH TISI IMPORT PERMIT. 18/05 : RECEIVED TISI. INSUFFICIENT FUNDS PARK AT SADAO. 21/05 : CROSS SADAO BORDER. | Q29: Pass
A30: 17 | B30: 46155 | C30: 20 | D30: TH | I30: 8260099741 | J30: 5
A31: 18 | B31: 46156 | C31: 20 | D31: TH | E31: KFD 9155 | F31: EHUU5550188 | G31: 1002832833 | H31: 3015147652 | I31: 8260099832 | J31: 68 | K31: 5407.79 | L31: 62.435 | M31: 46158 | N31: 0.625 | O31: Pass | Q31: Pass
A32: 19 | B32: 46156 | C32: 20 | D32: TH | E32: KGB 9855 | F32: EHUU5550206 | G32: 1002832835 | H32: 3015147877 | I32: 8260099833 | J32: 101 | K32: 5322.25 | L32: 57.696 | M32: 46158 | N32: 0.70833333 | O32: Pass | Q32: Pass
A33: 20 | B33: 46157 | C33: 20 | D33: TH | E33: KDW 8755 | F33: FKTT5550477 | G33: 1002832834 | H33: 3015148636 | I33: 8260099915 | J33: 125 | K33: 5517.47 | L33: 58.788 | M33: 46163 | N33: 0.77569444 | O33: Fail | P33: INSUFFICIENT FUNDS PARK AT SADAO. 20/05 : CROSS SADAO BORDER. | Q33: Pass
A34: 21 | B34: 46157 | C34: 20 | D34: TH | I34: 8260099916 | J34: 2
A35: 22 | B35: 46157 | C35: 20 | D35: TH | E35: KFB 5755 | F35: EHUU5550529 | G35: 1002832836 | H35: 3015148651 | I35: 8260099917 | J35: 41 | K35: 3398.35 | L35: 52.481 | M35: 46163 | N35: 0.75694444 | O35: Fail | P35: INSUFFICIENT FUNDS PARK AT SADAO. 20/05 : CROSS SADAO BORDER. | Q35: Pass
A36: 23 | B36: 46157 | C36: 20 | D36: TH | I36: 8260099918 | J36: 2
A37: 24 | B37: 46160 | C37: 21 | D37: TH | E37: KFB 5755 | F37: EHUU5550547 | G37: 1002832839 | H37: 3015151767 | I37: 8260099984 | J37: 166 | K37: 5277.92 | L37: 59.882 | M37: 46172 | N37: 0.47222222 | O37: Fail | P37: DETAINED AT PDC DUE TO 1 ITEM (152) REQUIRE TH TISI IMPORT PERMIT. 20/05 : RECEIVED INCORRECT TISI. 26/05 : RECEIVED REVISED TISI. 28/05 : TRUCK OUT FROM PDC. | Q37: Pass
A38: 25 | B38: 46160 | C38: 21 | D38: TH | E38: BJQ 6055 | F38: CICU2627830 | G38: 1002832837 | H38: 3015151771 | I38: 8260099985 | J38: 77 | K38: 5916.66 | L38: 55.294 | M38: 46164 | N38: 0.5 | O38: Fail | P38: INSUFFICIENT FUNDS PARK AT SADAO. 21/05 : CROSS SADAO BORDER. | Q38: Pass
A39: 26 | B39: 46160 | C39: 21 | D39: TH | I39: 8260099986 | J39: 2
A40: 27 | B40: 46161 | C40: 21 | D40: TH | E40: KEJ 9255 | F40: WHLU5561366 | G40: 1002832838 | H40: 3015154750 | I40: 8260100060 | J40: 55 | K40: 6666.7 | L40: 55.86 | M40: 46164 | N40: 0.44375 | O40: Fail | P40: INSUFFICIENT FUNDS PARK AT SADAO. 21/05 : CROSS SADAO BORDER. | Q40: Pass
A41: 28 | B41: 46161 | C41: 21 | D41: TH | E41: KFD8755 | F41: EHUU5550079 | G41: 1002898208 | H41: 3015154614 | I41: 8260100061 | J41: 90 | K41: 6715.707 | M41: 46164 | N41: 0.75 | O41: Fail | P41: INSUFFICIENT FUNDS PARK AT SADAO. 21/05 : CROSS SADAO BORDER. | Q41: Pass
A42: 29 | B42: 46162 | C42: 21 | D42: TH | E42: KEA 5955 | F42: EHUU5550306 | G42: 1002898210 | H42: 3015157849 | I42: 8260100127 | J42: 65 | K42: 8792.62 | L42: 56.534 | M42: 46164 | N42: 0.5 | O42: Pass | Q42: Pass
...
